Workbook

Sheet Keywords
A1: Positive | B1: Negative
A2: good | B2: bad
A3: great | B3: poor
A4: excellent | B4: not working
A5: love | B5: error
A6: best | B6: slow
A7: nice | B7: terrible
A8: happy | B8: hate
A9: amazing | B9: worst
A10: awesome | B10: failed
A11: perfect | B11: crash
A12: better | B12: can't
... A14: easy | B14: low
A15: thank
A16: Thank

Sheet Reviews
A1: Review | B1: Rating | C1: Formula | D1: AVERAGE
A2: My acc my moneys | B2: 1 | C2: =IF(AND(SUMPRODUCT(--ISNUMBER(SEARCH(TRIM(Keywords!$A$2:$A$16),A2)))>0, SUMPRODUCT(--ISNUMBER(SEARCH(TRIM(Keywords!$B$2:$B$14),A2)))>0),"Neutral", IF(SUMPRODUCT(--ISNUMBER(SEARCH(TRIM(Keywords!$A$2:$A$16),A2)))>0,"Positive", IF(SUMPRODUCT(--ISNUMBER(SEARCH(TRIM(Keywords!$A$2:$B$14),A2)))>0,"Negative","Neutral"))) -> Neutral | D2: =AVERAGEIF($C:$C,"Neutral",$B:$B) -> 3.4007156
A3: Thank | B3: 5 | C3: =IF(AND(SUMPRODUCT(--ISNUMBER(SEARCH(TRIM(Keywords!$A$2:$A$16),A3)))>0, SUMPRODUCT(--ISNUMBER(SEARCH(TRIM(Keywords!$B$2:$B$14),A3)))>0),"Neutral", IF(SUMPRODUCT(--ISNUMBER(SEARCH(TRIM(Keywords!$A$2:$A$16),A3)))>0,"Positive", IF(SUMPRODUCT(--ISNUMBER(SEARCH(TRIM(Keywords!$A$2:$B$14),A3)))>0,"Negative","Neutral"))) -> Positive | D3: =AVERAGEIF($C:$C,"Positive",$B:$B) -> 4.6233611
A4: I'm asking for a face scan again to open an account | B4: 3 | C4: =IF(AND(SUMPRODUCT(--ISNUMBER(SEARCH(TRIM(Keywords!$A$2:$A$16),A4)))>0, SUMPRODUCT(--ISNUMBER(SEARCH(TRIM(Keywords!$B$2:$B$14),A4)))>0),"Neutral", IF(SUMPRODUCT(--ISNUMBER(SEARCH(TRIM(Keywords!$A$2:$A$16),A4)))>0,"Positive", IF(SUMPRODUCT(--ISNUMBER(SEARCH(TRIM(Keywords!$A$2:$B$14),A4)))>0,"Negative","Neutral"))) -> Neutral
A5: good appointment for | B5: 2 | C5: =IF(AND(SUMPRODUCT(--ISNUMBER(SEARCH(TRIM(Keywords!$A$2:$A$16),A5)))>0, SUMPRODUCT(--ISNUMBER(SEARCH(TRIM(Keywords!$B$2:$B$14),A5)))>0),"Neutral", IF(SUMPRODUCT(--ISNUMBER(SEARCH(TRIM(Keywords!$A$2:$A$16),A5)))>0,"Positive", IF(SUMPRODUCT(--ISNUMBER(SEARCH(TRIM(Keywords!$A$2:$B$14),A5)))>0,"Negative","Neutral"))) -> Positive
A6: good | B6: 5 | C6: =IF(AND(SUMPRODUCT(--ISNUMBER(SEARCH(TRIM(Keywords!$A$2:$A$16),A6)))>0, SUMPRODUCT(--ISNUMBER(SEARCH(TRIM(Keywords!$B$2:$B$14),A6)))>0),"Neutral", IF(SUMPRODUCT(--ISNUMBER(SEARCH(TRIM(Keywords!$A$2:$A$16),A6)))>0,"Positive", IF(SUMPRODUCT(--ISNUMBER(SEARCH(TRIM(Keywords!$A$2:$B$14),A6)))>0,"Negative","Neutral"))) -> Positive
A7: like | B7: 3 | C7: =IF(AND(SUMPRODUCT(--ISNUMBER(SEARCH(TRIM(Keywords!$A$2:$A$16),A7)))>0, SUMPRODUCT(--ISNUMBER(SEARCH(TRIM(Keywords!$B$2:$B$14),A7)))>0),"Neutral", IF(SUMPRODUCT(--ISNUMBER(SEARCH(TRIM(Keywords!$A$2:$A$16),A7)))>0,"Positive", IF(SUMPRODUCT(--ISNUMBER(SEARCH(TRIM(Keywords!$A$2:$B$14),A7)))>0,"Negative","Neutral"))) -> Neutral
A8: good | B8: 4 | C8: =IF(AND(SUMPRODUCT(--ISNUMBER(SEARCH(TRIM(Keywords!$A$2:$A$16),A8)))>0, SUMPRODUCT(--ISNUMBER(SEARCH(TRIM(Keywords!$B$2:$B$14),A8)))>0),"Neutral", IF(SUMPRODUCT(--ISNUMBER(SEARCH(TRIM(Keywords!$A$2:$A$16),A8)))>0,"Positive", IF(SUMPRODUCT(--ISNUMBER(SEARCH(TRIM(Keywords!$A$2:$B$14),A8)))>0,"Negative","Neutral"))) -> Positive
A9: GOOD APP FOR BUSINESS | B9: 5 | C9: =IF(AND(SUMPRODUCT(--ISNUMBER(SEARCH(TRIM(Keywords!$A$2:$A$16),A9)))>0, SUMPRODUCT(--ISNUMBER(SEARCH(TRIM(Keywords!$B$2:$B$14),A9)))>0),"Neutral", IF(SUMPRODUCT(--ISNUMBER(SEARCH(TRIM(Keywords!$A$2:$A$16),A9)))>0,"Positive", IF(SUMPRODUCT(--ISNUMBER(SEARCH(TRIM(Keywords!$A$2:$B$14),A9)))>0,"Negative","Neutral"))) -> Positive
A10: good | B10: 4 | C10: =IF(AND(SUMPRODUCT(--ISNUMBER(SEARCH(TRIM(Keywords!$A$2:$A$16),A10)))>0, SUMPRODUCT(--ISNUMBER(SEARCH(TRIM(Keywords!$B$2:$B$14),A10)))>0),"Neutral", IF(SUMPRODUCT(--ISNUMBER(SEARCH(TRIM(Keywords!$A$2:$A$16),A10)))>0,"Positive", IF(SUMPRODUCT(--ISNUMBER(SEARCH(TRIM(Keywords!$A$2:$B$14),A10)))>0,"Negative","Neutral"))) -> Positive
A11: ok | B11: 3 | C11: =IF(AND(SUMPRODUCT(--ISNUMBER(SEARCH(TRIM(Keywords!$A$2:$A$16),A11)))>0, SUMPRODUCT(--ISNUMBER(SEARCH(TRIM(Keywords!$B$2:$B$14),A11)))>0),"Neutral", IF(SUMPRODUCT(--ISNUMBER(SEARCH(TRIM(Keywords!$A$2:$A$16),A11)))>0,"Positive", IF(SUMPRODUCT(--ISNUMBER(SEARCH(TRIM(Keywords!$A$2:$B$14),A11)))>0,"Negative","Neutral"))) -> Neutral
A12: Good | B12: 4 | C12: =IF(AND(SUMPRODUCT(--ISNUMBER(SEARCH(TRIM(Keywords!$A$2:$A$16),A12)))>0, SUMPRODUCT(--ISNUMBER(SEARCH(TRIM(Keywords!$B$2:$B$14),A12)))>0),"Neutral", IF(SUMPRODUCT(--ISNUMBER(SEARCH(TRIM(Keywords!$A$2:$A$16),A12)))>0,"Positive", IF(SUMPRODUCT(--ISNUMBER(SEARCH(TRIM(Keywords!$A$2:$B$14),A12)))>0,"Negative","Neutral"))) -> Positive
A13: Good | B13: 4 | C13: =IF(AND(SUMPRODUCT(--ISNUMBER(SEARCH(TRIM(Keywords!$A$2:$A$16),A13)))>0, SUMPRODUCT(--ISNUMBER(SEARCH(TRIM(Keywords!$B$2:$B$14),A13)))>0),"Neutral", IF(SUMPRODUCT(--ISNUMBER(SEARCH(TRIM(Keywords!$A$2:$A$16),A13)))>0,"Positive", IF(SUMPRODUCT(--ISNUMBER(SEARCH(TRIM(Keywords!$A$2:$B$14),A13)))>0,"Negative","Neutral"))) -> Positive
A14: ok | B14: 3 | C14: =IF(AND(SUMPRODUCT(--ISNUMBER(SEARCH(TRIM(Keywords!$A$2:$A$16),A14)))>0, SUMPRODUCT(--ISNUMBER(SEARCH(TRIM(Keywords!$B$2:$B$14),A14)))>0),"Neutral", IF(SUMPRODUCT(--ISNUMBER(SEARCH(TRIM(Keywords!$A$2:$A$16),A14)))>0,"Positive", IF(SUMPRODUCT(--ISNUMBER(SEARCH(TRIM(Keywords!$A$2:$B$14),A14)))>0,"Negative","Neutral"))) -> Neutral
A15: very good | B15: 5 | C15: =IF(AND(SUMPRODUCT(--ISNUMBER(SEARCH(TRIM(Keywords!$A$2:$A$16),A15)))>0, SUMPRODUCT(--ISNUMBER(SEARCH(TRIM(Keywords!$B$2:$B$14),A15)))>0),"Neutral", IF(SUMPRODUCT(--ISNUMBER(SEARCH(TRIM(Keywords!$A$2:$A$16),A15)))>0,"Positive", IF(SUMPRODUCT(--ISNUMBER(SEARCH(TRIM(Keywords!$A$2:$B$14),A15)))>0,"Negative","Neutral"))) -> Positive
... A21: Hey! | B21: 3 | C21: =IF(AND(SUMPRODUCT(--ISNUMBER(SEARCH(TRIM(Keywords!$A$2:$A$16),A21)))>0, SUMPRODUCT(--ISNUMBER(SEARCH(TRIM(Keywords!$B$2:$B$14),A21)))>0),"Neutral", IF(SUMPRODUCT(--ISNUMBER(SEARCH(TRIM(Keywords!$A$2:$A$16),A21)))>0,"Positive", IF(SUMPRODUCT(--ISNUMBER(SEARCH(TRIM(Keywords!$A$2:$B$14),A21)))>0,"Negative","Neutral"))) -> Neutral
A22: Can't get back into kpay acc | B22: 1 | C22: =IF(AND(SUMPRODUCT(--ISNUMBER(SEARCH(TRIM(Keywords!$A$2:$A$16),A22)))>0, SUMPRODUCT(--ISNUMBER(SEARCH(TRIM(Keywords!$B$2:$B$14),A22)))>0),"Neutral", IF(SUMPRODUCT(--ISNUMBER(SEARCH(TRIM(Keywords!$A$2:$A$16),A22)))>0,"Positive", IF(SUMPRODUCT(--ISNUMBER(SEARCH(TRIM(Keywords!$A$2:$B$14),A22)))>0,"Negative","Neutral"))) -> Negative | D22: =AVERAGEIF($C:$C,"Negative",$B:$B) -> 1.8039216
A23: kolaythu | B23: 1 | C23: =IF(AND(SUMPRODUCT(--ISNUMBER(SEARCH(TRIM(Keywords!$A$2:$A$16),A23)))>0, SUMPRODUCT(--ISNUMBER(SEARCH(TRIM(Keywords!$B$2:$B$14),A23)))>0),"Neutral", IF(SUMPRODUCT(--ISNUMBER(SEARCH(TRIM(Keywords!$A$2:$A$16),A23)))>0,"Positive", IF(SUMPRODUCT(--ISNUMBER(SEARCH(TRIM(Keywords!$A$2:$B$14),A23)))>0,"Negative","Neutral"))) -> Neutral
A24: very good | B24: 5 | C24: =IF(AND(SUMPRODUCT(--ISNUMBER(SEARCH(TRIM(Keywords!$A$2:$A$16),A24)))>0, SUMPRODUCT(--ISNUMBER(SEARCH(TRIM(Keywords!$B$2:$B$14),A24)))>0),"Neutral", IF(SUMPRODUCT(--ISNUMBER(SEARCH(TRIM(Keywords!$A$2:$A$16),A24)))>0,"Positive", IF(SUMPRODUCT(--ISNUMBER(SEARCH(TRIM(Keywords!$A$2:$B$14),A24)))>0,"Negative","Neutral"))) -> Positive
A25: It's a big scam app. I added 5K to my phone bill. It's gone. The phone bill didn't arrive. The money went out | B25: 1 | C25: =IF(AND(SUMPRODUCT(--ISNUMBER(SEARCH(TRIM(Keywords!$A$2:$A$16),A25)))>0, SUMPRODUCT(--ISNUMBER(SEARCH(TRIM(Keywords!$B$2:$B$14),A25)))>0),"Neutral", IF(SUMPRODUCT(--ISNUMBER(SEARCH(TRIM(Keywords!$A$2:$A$16),A25)))>0,"Positive", IF(SUMPRODUCT(--ISNUMBER(SEARCH(TRIM(Keywords!$A$2:$B$14),A25)))>0,"Negative","Neutral"))) -> Neutral
A26: bad service, | B26: 1 | C26: =IF(AND(SUMPRODUCT(--ISNUMBER(SEARCH(TRIM(Keywords!$A$2:$A$16),A26)))>0, SUMPRODUCT(--ISNUMBER(SEARCH(TRIM(Keywords!$B$2:$B$14),A26)))>0),"Neutral", IF(SUMPRODUCT(--ISNUMBER(SEARCH(TRIM(Keywords!$A$2:$A$16),A26)))>0,"Positive", IF(SUMPRODUCT(--ISNUMBER(SEARCH(TRIM(Keywords!$A$2:$B$14),A26)))>0,"Negative","Neutral"))) -> Negative
A27: Good | B27: 4 | C27: =IF(AND(SUMPRODUCT(--ISNUMBER(SEARCH(TRIM(Keywords!$A$2:$A$16),A27)))>0, SUMPRODUCT(--ISNUMBER(SEARCH(TRIM(Keywords!$B$2:$B$14),A27)))>0),"Neutral", IF(SUMPRODUCT(--ISNUMBER(SEARCH(TRIM(Keywords!$A$2:$A$16),A27)))>0,"Positive", IF(SUMPRODUCT(--ISNUMBER(SEARCH(TRIM(Keywords!$A$2:$B$14),A27)))>0,"Negative","Neutral"))) -> Positive
A28: good | B28: 5 | C28: =IF(AND(SUMPRODUCT(--ISNUMBER(SEARCH(TRIM(Keywords!$A$2:$A$16),A28)))>0, SUMPRODUCT(--ISNUMBER(SEARCH(TRIM(Keywords!$B$2:$B$14),A28)))>0),"Neutral", IF(SUMPRODUCT(--ISNUMBER(SEARCH(TRIM(Keywords!$A$2:$A$16),A28)))>0,"Positive", IF(SUMPRODUCT(--ISNUMBER(SEARCH(TRIM(Keywords!$A$2:$B$14),A28)))>0,"Negative","Neutral"))) -> Positive
A29: I don't like this app | B29: 1 | C29: =IF(AND(SUMPRODUCT(--ISNUMBER(SEARCH(TRIM(Keywords!$A$2:$A$16),A29)))>0, SUMPRODUCT(--ISNUMBER(SEARCH(TRIM(Keywords!$B$2:$B$14),A29)))>0),"Neutral", IF(SUMPRODUCT(--ISNUMBER(SEARCH(TRIM(Keywords!$A$2:$A$16),A29)))>0,"Positive", IF(SUMPRODUCT(--ISNUMBER(SEARCH(TRIM(Keywords!$A$2:$B$14),A29)))>0,"Negative","Neutral"))) -> Negative
A30: good | B30: 4 | C30: =IF(AND(SUMPRODUCT(--ISNUMBER(SEARCH(TRIM(Keywords!$A$2:$A$16),A30)))>0, SUMPRODUCT(--ISNUMBER(SEARCH(TRIM(Keywords!$B$2:$B$14),A30)))>0),"Neutral", IF(SUMPRODUCT(--ISNUMBER(SEARCH(TRIM(Keywords!$A$2:$A$16),A30)))>0,"Positive", IF(SUMPRODUCT(--ISNUMBER(SEARCH(TRIM(Keywords!$A$2:$B$14),A30)))>0,"Negative","Neutral"))) -> Positive
A31: SoOkgood | B31: 5 | C31: =IF(AND(SUMPRODUCT(--ISNUMBER(SEARCH(TRIM(Keywords!$A$2:$A$16),A31)))>0, SUMPRODUCT(--ISNUMBER(SEARCH(TRIM(Keywords!$B$2:$B$14),A31)))>0),"Neutral", IF(SUMPRODUCT(--ISNUMBER(SEARCH(TRIM(Keywords!$A$2:$A$16),A31)))>0,"Positive", IF(SUMPRODUCT(--ISNUMBER(SEARCH(TRIM(Keywords!$A$2:$B$14),A31)))>0,"Negative","Neutral"))) -> Positive
A32: Nice App for payment | B32: 4 | C32: =IF(AND(SUMPRODUCT(--ISNUMBER(SEARCH(TRIM(Keywords!$A$2:$A$16),A32)))>0, SUMPRODUCT(--ISNUMBER(SEARCH(TRIM(Keywords!$B$2:$B$14),A32)))>0),"Neutral", IF(SUMPRODUCT(--ISNUMBER(SEARCH(TRIM(Keywords!$A$2:$A$16),A32)))>0,"Positive", IF(SUMPRODUCT(--ISNUMBER(SEARCH(TRIM(Keywords!$A$2:$B$14),A32)))>0,"Negative","Neutral"))) -> Positive
A33: ok | B33: 3 | C33: =IF(AND(SUMPRODUCT(--ISNUMBER(SEARCH(TRIM(Keywords!$A$2:$A$16),A33)))>0, SUMPRODUCT(--ISNUMBER(SEARCH(TRIM(Keywords!$B$2:$B$14),A33)))>0),"Neutral", IF(SUMPRODUCT(--ISNUMBER(SEARCH(TRIM(Keywords!$A$2:$A$16),A33)))>0,"Positive", IF(SUMPRODUCT(--ISNUMBER(SEARCH(TRIM(Keywords!$A$2:$B$14),A33)))>0,"Negative","Neutral"))) -> Neutral
A34: so good | B34: 4 | C34: =IF(AND(SUMPRODUCT(--ISNUMBER(SEARCH(TRIM(Keywords!$A$2:$A$16),A34)))>0, SUMPRODUCT(--ISNUMBER(SEARCH(TRIM(Keywords!$B$2:$B$14),A34)))>0),"Neutral", IF(SUMPRODUCT(--ISNUMBER(SEARCH(TRIM(Keywords!$A$2:$A$16),A34)))>0,"Positive", IF(SUMPRODUCT(--ISNUMBER(SEARCH(TRIM(Keywords!$A$2:$B$14),A34)))>0,"Negative","Neutral"))) -> Positive
... A170: that's cool | B170: 3 | C170: =IF(AND(SUMPRODUCT(--ISNUMBER(SEARCH(TRIM(Keywords!$A$2:$A$16),A170)))>0, SUMPRODUCT(--ISNUMBER(SEARCH(TRIM(Keywords!$B$2:$B$14),A170)))>0),"Neutral", IF(SUMPRODUCT(--ISNUMBER(SEARCH(TRIM(Keywords!$A$2:$A$16),A170)))>0,"Positive", IF(SUMPRODUCT(--ISNUMBER(SEARCH(TRIM(Keywords!$A$2:$B$14),A170)))>0,"Negative","Neutral"))) -> Neutral
A171: 13445667 | B171: 3 | C171: =IF(AND(SUMPRODUCT(--ISNUMBER(SEARCH(TRIM(Keywords!$A$2:$A$16),A171)))>0, SUMPRODUCT(--ISNUMBER(SEARCH(TRIM(Keywords!$B$2:$B$14),A171)))>0),"Neutral", IF(SUMPRODUCT(--ISNUMBER(SEARCH(TRIM(Keywords!$A$2:$A$16),A171)))>0,"Positive", IF(SUMPRODUCT(--ISNUMBER(SEARCH(TRIM(Keywords!$A$2:$B$14),A171)))>0,"Negative","Neutral"))) -> Neutral
A172: useful app | B172: 3 | C172: =IF(AND(SUMPRODUCT(--ISNUMBER(SEARCH(TRIM(Keywords!$A$2:$A$16),A172)))>0, SUMPRODUCT(--ISNUMBER(SEARCH(TRIM(Keywords!$B$2:$B$14),A172)))>0),"Neutral", IF(SUMPRODUCT(--ISNUMBER(SEARCH(TRIM(Keywords!$A$2:$A$16),A172)))>0,"Positive", IF(SUMPRODUCT(--ISNUMBER(SEARCH(TRIM(Keywords!$A$2:$B$14),A172)))>0,"Negative","Neutral"))) -> Neutral
A173: good | B173: 5 | C173: =IF(AND(SUMPRODUCT(--ISNUMBER(SEARCH(TRIM(Keywords!$A$2:$A$16),A173)))>0, SUMPRODUCT(--ISNUMBER(SEARCH(TRIM(Keywords!$B$2:$B$14),A173)))>0),"Neutral", IF(SUMPRODUCT(--ISNUMBER(SEARCH(TRIM(Keywords!$A$2:$A$16),A173)))>0,"Positive", IF(SUMPRODUCT(--ISNUMBER(SEARCH(TRIM(Keywords!$A$2:$B$14),A173)))>0,"Negative","Neutral"))) -> Positive
A174: so good | B174: 5 | C174: =IF(AND(SUMPRODUCT(--ISNUMBER(SEARCH(TRIM(Keywords!$A$2:$A$16),A174)))>0, SUMPRODUCT(--ISNUMBER(SEARCH(TRIM(Keywords!$B$2:$B$14),A174)))>0),"Neutral", IF(SUMPRODUCT(--ISNUMBER(SEARCH(TRIM(Keywords!$A$2:$A$16),A174)))>0,"Positive", IF(SUMPRODUCT(--ISNUMBER(SEARCH(TRIM(Keywords!$A$2:$B$14),A174)))>0,"Negative","Neutral"))) -> Positive
A175: low bank service quality | B175: 1 | C175: =IF(AND(SUMPRODUCT(--ISNUMBER(SEARCH(TRIM(Keywords!$A$2:$A$16),A175)))>0, SUMPRODUCT(--ISNUMBER(SEARCH(TRIM(Keywords!$B$2:$B$14),A175)))>0),"Neutral", IF(SUMPRODUCT(--ISNUMBER(SEARCH(TRIM(Keywords!$A$2:$A$16),A175)))>0,"Positive", IF(SUMPRODUCT(--ISNUMBER(SEARCH(TRIM(Keywords!$A$2:$B$14),A175)))>0,"Negative","Neutral"))) -> Negative
A176: very good | B176: 4 | C176: =IF(AND(SUMPRODUCT(--ISNUMBER(SEARCH(TRIM(Keywords!$A$2:$A$16),A176)))>0, SUMPRODUCT(--ISNUMBER(SEARCH(TRIM(Keywords!$B$2:$B$14),A176)))>0),"Neutral", IF(SUMPRODUCT(--ISNUMBER(SEARCH(TRIM(Keywords!$A$2:$A$16),A176)))>0,"Positive", IF(SUMPRODUCT(--ISNUMBER(SEARCH(TRIM(Keywords!$A$2:$B$14),A176)))>0,"Negative","Neutral"))) -> Positive
A177: app into not dainger good like | B177: 4 | C177: =IF(AND(SUMPRODUCT(--ISNUMBER(SEARCH(TRIM(Keywords!$A$2:$A$16),A177)))>0, SUMPRODUCT(--ISNUMBER(SEARCH(TRIM(Keywords!$B$2:$B$14),A177)))>0),"Neutral", IF(SUMPRODUCT(--ISNUMBER(SEARCH(TRIM(Keywords!$A$2:$A$16),A177)))>0,"Positive", IF(SUMPRODUCT(--ISNUMBER(SEARCH(TRIM(Keywords!$A$2:$B$14),A177)))>0,"Negative","Neutral"))) -> Positive
A178: good | B178: 5 | C178: =IF(AND(SUMPRODUCT(--ISNUMBER(SEARCH(TRIM(Keywords!$A$2:$A$16),A178)))>0, SUMPRODUCT(--ISNUMBER(SEARCH(TRIM(Keywords!$B$2:$B$14),A178)))>0),"Neutral", IF(SUMPRODUCT(--ISNUMBER(SEARCH(TRIM(Keywords!$A$2:$A$16),A178)))>0,"Positive", IF(SUMPRODUCT(--ISNUMBER(SEARCH(TRIM(Keywords!$A$2:$B$14),A178)))>0,"Negative","Neutral"))) -> Positive
A179: good | B179: 5 | C179: =IF(AND(SUMPRODUCT(--ISNUMBER(SEARCH(TRIM(Keywords!$A$2:$A$16),A179)))>0, SUMPRODUCT(--ISNUMBER(SEARCH(TRIM(Keywords!$B$2:$B$14),A179)))>0),"Neutral", IF(SUMPRODUCT(--ISNUMBER(SEARCH(TRIM(Keywords!$A$2:$A$16),A179)))>0,"Positive", IF(SUMPRODUCT(--ISNUMBER(SEARCH(TRIM(Keywords!$A$2:$B$14),A179)))>0,"Negative","Neutral"))) -> Positive
A180: Thanks you .This App regular to money payment | B180: 5 | C180: =IF(AND(SUMPRODUCT(--ISNUMBER(SEARCH(TRIM(Keywords!$A$2:$A$16),A180)))>0, SUMPRODUCT(--ISNUMBER(SEARCH(TRIM(Keywords!$B$2:$B$14),A180)))>0),"Neutral", IF(SUMPRODUCT(--ISNUMBER(SEARCH(TRIM(Keywords!$A$2:$A$16),A180)))>0,"Positive", IF(SUMPRODUCT(--ISNUMBER(SEARCH(TRIM(Keywords!$A$2:$B$14),A180)))>0,"Negative","Neutral"))) -> Positive
...

Sheet Sheet3
A1: Device Type | B1: Average Rating | C1: Frequency | D1: Percentage
A2: Phone | B2: 4.54 | C2: 1256 | D2: 0.84
A3: Tablet | B3: 4.01 | C3: 244 | D3: 0.16
A4: Total | C4: 1500 | D4: 1
A9: Month | B9: Average Rating | C9: Frequency | D9: Percentage
A10: Apr – May, 2025 | B10: 4.5 | C10: 248 | D10: 0.17
A11: Jun – Jul, 2025 | B11: 3.5 | C11: 460 | D11: 0.31
A12: Aug – Sep, 2025 | B12: 3.9 | C12: 453 | D12: 0.3
A13: Oct – Nov, 2025 | B13: 4.2 | C13: 339 | D13: 0.23
A14: Total | C14: 1500 | D14: 1
A17: Emoji | B17: Average Rating | C17: Frequency | D17: Percentage
A18: Positive | B18: 4.1 | C18: 14 | D18: 0.01
A19: Neutral | B19: 0 | C19: 0 | D19: 0
A20: Negative | B20: 0 | C20: 0 | D20: 0
A21: Nil | B21: 0 | C21: 1486 | D21: 0.99
A22: Total | C22: 1500 | D22: 1
A24: Language | B24: Average Rating | C24: Frequency | D24: Percentage
A25: English | B25: 4.2 | C25: 1344 | D25: 0.9
A26: Burmese | B26: 2.3 | C26: 96 | D26: 0.06
A27: Mixed | B27: 3.4 | C27: 60 | D27: 0.04
A28: Total | C28: 1500 | D28: 1
A31: Sentiment | B31: Average Rating | C31: Frequency | D31: Percentage
A32: Positive | B32: 4.62 | C32: 790 | D32: 0.53
A33: Neutral | B33: 3.04 | C33: 420 | D33: 0.28
A34: Negative | B34: 1.8 | C34: 290 | D34: 0.19
A35: Total | C35: 1500 | D35: 1
